<?xml version="1.0" ?>

<robot name="ur5">
  <link name="world"/>
  <joint name="world_joint" type="fixed">
    <parent link="world"/>
    <child link="ur5/base_link"/>
    <origin rpy="0.0 0.0 0" xyz="0.0 0.0 0"/>
  </joint>

  <link name="ur5/base_link">
    <visual>
      <geometry>
        <mesh filename="../meshes/ur_description/meshes/ur5/visual/base.dae"/>
      </geometry>
    </visual>
  </link>
  <joint name="shoulder_pan_joint" type="revolute">
    <parent link="ur5/base_link"/>
    <child link="ur5/shoulder_link"/>
    <origin rpy="0.0 0.0 0.0" xyz="0.0 0.0 0.089159"/>
    <axis xyz="0 0 1"/>
    <limit effort="150.0" lower="-3.14159265" upper="3.14159265" velocity="3.15"/>
  </joint>
  <link name="ur5/shoulder_link">
    <visual>
      <geometry>
        <mesh filename="../meshes/ur_description/meshes/ur5/visual/shoulder.dae"/>
      </geometry>
    </visual>
  </link>
  <joint name="shoulder_lift_joint" type="revolute">
    <parent link="ur5/shoulder_link"/>
    <child link="ur5/upper_arm_link"/>
    <origin rpy="0.0 1.570796325 0.0" xyz="0.0 0.13585 0.0"/>
    <axis xyz="0 1 0"/>
    <limit effort="150.0" lower="-3.14159265" upper="3.14159265" velocity="3.15"/>
  </joint>
  <link name="ur5/upper_arm_link">
    <visual>
      <geometry>
        <mesh filename="../meshes/ur_description/meshes/ur5/visual/upperarm.dae"/>
      </geometry>
    </visual>
  </link>
  <joint name="elbow_joint" type="revolute">
    <parent link="ur5/upper_arm_link"/>
    <child link="ur5/forearm_link"/>
    <origin rpy="0.0 0.0 0.0" xyz="0.0 -0.1197 0.425"/>
    <axis xyz="0 1 0"/>
    <limit effort="150.0" lower="-3.14159265" upper="3.14159265" velocity="3.15"/>
  </joint>
  <link name="ur5/forearm_link">
    <visual>
      <geometry>
        <mesh filename="../meshes/ur_description/meshes/ur5/visual/forearm.dae"/>
      </geometry>
    </visual>
  </link>
  <joint name="wrist_1_joint" type="revolute">
    <parent link="ur5/forearm_link"/>
    <child link="ur5/wrist_1_link"/>
    <origin rpy="0.0 1.570796325 0.0" xyz="0.0 0.0 0.39225"/>
    <axis xyz="0 1 0"/>
    <limit effort="28.0" lower="-3.14159265" upper="3.14159265" velocity="3.2"/>
  </joint>
  <link name="ur5/wrist_1_link">
    <visual>
      <geometry>
        <mesh filename="../meshes/ur_description/meshes/ur5/visual/wrist1.dae"/>
      </geometry>
    </visual>
  </link>
  <joint name="wrist_2_joint" type="revolute">
    <parent link="ur5/wrist_1_link"/>
    <child link="ur5/wrist_2_link"/>
    <origin rpy="0.0 0.0 0.0" xyz="0.0 0.093 0.0"/>
    <axis xyz="0 0 1"/>
    <limit effort="28.0" lower="-3.14159265" upper="3.14159265" velocity="3.2"/>
  </joint>
  <link name="ur5/wrist_2_link">
    <visual>
      <geometry>
        <mesh filename="../meshes/ur_description/meshes/ur5/visual/wrist2.dae"/>
      </geometry>
    </visual>
  </link>
  <joint name="wrist_3_joint" type="revolute">
    <parent link="ur5/wrist_2_link"/>
    <child link="ur5/wrist_3_link"/>
    <origin rpy="0.0 0.0 0.0" xyz="0.0 0.0 0.09465"/>
    <axis xyz="0 1 0"/>
    <limit effort="28.0" lower="-3.14159265" upper="3.14159265" velocity="3.2"/>
  </joint>
  <link name="ur5/wrist_3_link">
    <visual>
      <geometry>
        <mesh filename="../meshes/ur_description/meshes/ur5/visual/wrist3.dae"/>
      </geometry>
    </visual>
  </link>

   <joint name="ee_fixed_joint" type="fixed">
    <parent link="ur5/wrist_3_link"/>
    <child link="ur5/ee_link"/>
    <origin rpy="0.0 0.0 1.57079632679" xyz="0.0 0.0823 0.0"/>
  </joint>
  <link name="ur5/ee_link">
    <collision>
      <geometry>
        <box size="0.01 0.01 0.01"/>
      </geometry>
      <origin rpy="0 0 0" xyz="-0.01 0 0"/>
    </collision>
  </link>
    <joint name='left_gripper_motor' type='prismatic'>
    <parent link="ur5/wrist_3_link"/>
    <child link="ur5/left_gripper"/>
    <origin rpy="-1.57 0.0 0.0" xyz="-0.06 0.1 0.005"/>
    <axis xyz="1 0 0"/>
    <limit effort="10.0" lower="-0.00" upper="0.04" velocity="1000"/>
    <dynamics damping="0.0" friction="0.0"/>
  </joint>
<link name="ur5/left_gripper">
    <contact>
      <lateral_friction value="10.0"/>
      <inertia_scaling value="3.0"/>
    </contact>
    <inertial>
      <origin rpy="0 0 0" xyz="0 0 0.05"/>
       <mass value=".2"/>
       <inertia ixx="0.1" ixy="0" ixz="0" iyy="0.1" iyz="0" izz="0.1"/>
    </inertial>
    <visual>
      <origin rpy="0 0 4.71239" xyz="0 0 0"/>
      <geometry>
        <mesh filename="../meshes/ur5/visual/l_gripper_tip_scaled.stl" scale="1 1 1"/>
      </geometry>
    </visual>
    <collision>
      <origin rpy="0 0 0" xyz="0 0 0.042"/>
      <geometry>
    <box size="0.02 0.02 0.15"/>
      </geometry>
    </collision>
  </link>
    <joint name='right_gripper_motor' type='prismatic'>
    <parent link="ur5/wrist_3_link"/>
    <child link="ur5/right_gripper"/>
    <origin rpy="-1.57 0.0 0.0" xyz="0.06 0.1 -0.005"/>
    <axis xyz="1 0 0"/>
    <limit effort="10.0" lower="-0.04" upper="0.0" velocity="1000"/>
    <dynamics damping="0.0" friction="0.0"/>
  </joint>
  <link name="ur5/right_gripper">
    <contact>
      <lateral_friction value="10.0"/>
      <inertia_scaling value="3.0"/>
    </contact>
    <inertial>
      <origin rpy="0 0 0" xyz="0 0 0.05"/>
       <mass value=".2"/>
       <inertia ixx="0.1" ixy="0" ixz="0" iyy="0.1" iyz="0" izz="0.1"/>
    </inertial>
    <visual>
      <origin rpy="0 0 1.5708" xyz="0 0 0"/>
      <geometry>
        <mesh filename="../meshes/ur5/visual/l_gripper_tip_scaled.stl" scale="1 1 1"/>
      </geometry>
    </visual>
    <collision>
      <origin rpy="0 0 0" xyz="0 0 0.042"/>
      <geometry>
    <box size="0.02 0.02 0.15"/>
      </geometry>
    </collision>
  </link>
</robot>
